Workbook

Sheet Mode d'emploi
A1: Relecture du contenu V5 (bloc 2)
A2: Rien de ce tableur n'apparaît dans l'app tant que ce n'est pas validé : tout est importé « à valider ».
A4: Ce que tu remplis (cases jaunes)
A5: Validé | B5: oui / non / à revoir | C5: oui : l'exercice ou l'entraînement devient visible. non : il reste caché. à revoir : précise dans Commentaire.
A6: Vidéo OK | B6: oui / non | C6: non : je cherche une autre vidéo.
A7: Commentaire | B7: texte libre | C7: Ce qu'il faut changer (consigne, niveau, intensité, vidéo...).
A8: Exemple | B8: Validé = oui | C8: Vidéo OK = non ; Commentaire = « vidéo trop rapide, en trouver une plus pédagogique »
A10: Où en est la relecture | B10: Nombre
A11: Exercices au total | B11: =COUNTA(Exercices!A2:A147) -> 146
A12: Dont nouveaux | B12: =COUNTIF(Exercices!C2:C147,"Nouveau") -> 103
A13: Exercices validés | B13: =COUNTIF(Exercices!D2:D147,"oui") -> 0
A14: Exercices à revoir | B14: =COUNTIF(Exercices!D2:D147,"à revoir") -> 0
A15: Vidéos refusées | B15: =COUNTIF(Exercices!E2:E147,"non") -> 0
A16: Entraînements au total | B16: =COUNTA(Entraînements!A2:A76) -> 75
A17: Entraînements validés | B17: =COUNTIF(Entraînements!D2:D76,"oui") -> 0
A18: Exercices restant à relire | B18: =COUNTA(Exercices!A2:A147)-COUNTA(Exercices!D2:D147) -> 146
A20: Poids pour estimer les calories (kg) | B20: 60 | C20: Exemple : 60 kg. Change-le pour voir les calories des entraînements à ton poids.
A22: À savoir
A23: Un entraînement validé ne s'affiche que si tous ses exercices sont validés aussi.
A24: Les 43 exercices existants gardent leur nom, leurs consignes et leurs niveaux : seules les étiquettes, le tutoriel, la source et la vidéo sont nouveaux.
A25: Calories : MET x poids x durée (Compendium 2024). La colonne des entraînements prend 60 kg pour exemple ; l'app utilisera le poids du profil.
A26: Sources : free-exercise-db (base ouverte, domaine public), NHS, Harvard Health, Yoga Journal, Yogamatters et références scientifiques. Aucun texte n'est copié.
A27: Vidéos : liens YouTube trouvés en ligne, en français quand c'était possible. Je ne peux pas les regarder : c'est à toi de vérifier qu'elles montrent le bon mouvement.

Sheet Exercices
A1: Identifiant | B1: Nom | C1: Statut | D1: Validé | E1: Vidéo OK | F1: Commentaire | G1: Discipline | H1: Zones | I1: Objectifs | J1: Intensité (1 à 5) | K1: Sauts | L1: Matériel nécessaire | M1: Par défaut | N1: Niveaux | O1: Muscles principaux | P1: Muscles secondaires | Q1: MET (Compendium 2024) | R1: Consignes | S1: Précaution | T1: Respiration | U1: Erreurs fréquentes | V1: Sources | W1: Vidéo proposée
A2: squat | B2: Squat au poids du corps | C2: Nouveau | G2: renforcement | H2: jambes, fessiers | I2: renforcer, tonifier | J2: 2 | K2: non | L2: aucun | M2: 12 répétitions | N2: 1. Amplitude confortable (10 rép.) 2. Cuisses parallèles au sol (12 rép.) 3. Descente lente en 3 s (12 rép.) 4. Pause de 2 s en bas (15 rép.) | O2: Quadriceps, Grand fessier | P2: Ischio-jambiers, Adducteurs, Bas du dos (lombaires) | Q2: 3 (code 02056, Renforcement au poids du corps, général) | R2: Debout, pieds un peu plus écartés que les hanches, pointes légèrement ouvertes. Pousse les fesses en arrière et descends comme pour t'asseoir, poitrine ouverte. Remonte en poussant dans tout le pied, genoux dans l'axe des orteils. | S2: Descends seulement jusqu'où ton dos reste long et tes talons au sol. | T2: Inspire en descendant, expire en remontant. | U2: Genoux qui rentrent vers l'intérieur. Talons qui décollent. Dos qui s'arrondit en bas. | V2: free-exercise-db (domaine public), fiche Bodyweight Squat : https://github.com/yuhonas/free-exercise-db/blob/main/exercises/Bodyweight_Squat.json NHS, Strength exercises : https://www.nhs.uk/live-well/exercise/strength-and-flexibility-exercises/strength-exercises/ | W2: Comment faire des squats de la bonne façon au poids du corps ou avec charge (français) https://www.youtube.com/watch?v=EMfbjJWIllU
A3: squat_sumo | B3: Squat sumo | C3: Nouveau | G3: renforcement | H3: jambes, fessiers | I3: renforcer, tonifier | J3: 2 | K3: non | L3: aucun | M3: 12 répétitions | N3: 1. Amplitude confortable (10 rép.) 2. Cuisses parallèles au sol (12 rép.) 3. Pause de 2 s en bas (12 rép.) 4. Haltère tenu des deux mains (12 rép.) | O3: Adducteurs, Grand fessier, Quadriceps | P3: Ischio-jambiers | Q3: 3 (code 02056, Renforcement au poids du corps, général) | R3: Pieds bien plus écartés que les épaules, pointes tournées vers l'extérieur. Descends le bassin à la verticale, buste droit, genoux ouverts vers les pieds. Remonte en serrant les fessiers. | S3: Les genoux suivent toujours la direction des pointes de pied. | T3: Inspire en descendant, expire en remontant. | U3: Pencher le buste en avant. Laisser les genoux se refermer. | V3: free-exercise-db (domaine public), fiche Plie Dumbbell Squat : https://github.com/yuhonas/free-exercise-db/blob/main/exercises/Plie_Dumbbell_Squat.json | W3: Comment faire un squat sumo (français) https://www.youtube.com/watch?v=xnvkQeZ_XaE
A4: chaise_mur | B4: Chaise contre le mur | C4: Nouveau | G4: renforcement | H4: jambes | I4: renforcer, tonifier | J4: 3 | K4: non | L4: mur | M4: 30 s | N4: 1. Genoux peu fléchis (20 s) 2. Genoux peu fléchis (30 s) 3. Cuisses presque parallèles au sol (30 s) 4. Cuisses parallèles au sol (45 s) | O4: Quadriceps | P4: Grand fessier, Adducteurs | Q4: 3 (code 02056, Renforcement au poids du corps, général) | R4: Dos plaqué contre le mur, pieds à environ 50 cm du mur. Glisse vers le bas jusqu'à la hauteur choisie, genoux au-dessus des chevilles. Tiens la position, mains sur les cuisses ou bras croisés. | S4: Si une douleur apparaît dans le genou, remonte un peu. | T4: Respire calmement, sans bloquer. | U4: Genoux qui dépassent largement les orteils. Appuyer les mains sur les cuisses pour tricher. | V4: NHS, Strength exercises : https://www.nhs.uk/live-well/exercise/strength-and-flexibility-exercises/strength-exercises/ | W4: La chaise murale : endurance et cuisses sans matériel (tuto rapide) (français) https://www.youtube.com/watch?v=-NuqBMIgrcc
A5: fente_avant | B5: Fente avant | C5: Nouveau | G5: renforcement | H5: jambes, fessiers | I5: renforcer, tonifier | J5: 3 | K5: non | L5: aucun | M5: 10 répétitions | N5: 1. Fente sur place, petite amplitude (8 rép.) 2. Fente sur place (10 rép.) 3. Pas en avant puis retour (10 rép.) 4. Haltères en main (10 rép.) | O5: Quadriceps, Grand fessier | P5: Ischio-jambiers, Adducteurs | Q5: 3.8 (code 02022, Callisthénie modérée (pompes, fentes)) | R5: Debout, fais un grand pas en avant. Descends le genou arrière vers le sol, buste droit. Pousse sur le pied avant pour revenir. Alterne les jambes. | S5: Le genou avant reste au-dessus de la cheville. Tiens-toi à une chaise si l'équilibre est difficile. | T5: Inspire en descendant, expire en remontant. | U5: Pas trop court : le genou avant part loin devant. Buste penché vers l'avant. | V5: free-exercise-db (domaine public), fiche Bodyweight Walking Lunge : https://github.com/yuhonas/free-exercise-db/blob/main/exercises/Bodyweight_Walking_Lunge.json NHS, Strength exercises : https://www.nhs.uk/live-well/exercise/strength-and-flexibility-exercises/strength-exercises/ | W5: Comment faire les fentes : technique et erreurs à éviter (français) https://www.youtube.com/watch?v=HH9FQpjXw7A
A6: fente_arriere | B6: Fente arrière | C6: Nouveau | G6: renforcement | H6: jambes, fessiers | I6: renforcer, tonifier | J6: 2 | K6: non | L6: aucun | M6: 10 répétitions | N6: 1. Main sur une chaise, petite amplitude (8 rép.) 2. Sans appui (10 rép.) 3. Descente lente en 3 s (10 rép.) 4. Haltères en main (10 rép.) | O6: Grand fessier, Quadriceps | P6: Ischio-jambiers | Q6: 3.8 (code 02022, Callisthénie modérée (pompes, fentes)) | R6: Debout, recule un pied d'un grand pas. Fléchis les deux genoux, le genou arrière descend vers le sol. Reviens en poussant sur le talon avant. Alterne. | S6: Plus facile pour les genoux que la fente avant : bon choix pour commencer. | T6: Inspire en reculant, expire en revenant. | U6: Pieds sur la même ligne : on perd l'équilibre. Genou arrière qui tape le sol. | V6: free-exercise-db (domaine public), fiche Dumbbell Rear Lunge : https://github.com/yuhonas/free-exercise-db/blob/main/exercises/Dumbbell_Rear_Lunge.json | W6: Comment faire une fente arrière correctement ? (français) https://www.youtube.com/watch?v=Zz8DrsAUIZo
A7: fente_laterale | B7: Fente latérale | C7: Nouveau | G7: renforcement | H7: jambes, fessiers | I7: renforcer, tonifier, mobilite | J7: 2 | K7: non | L7: aucun | M7: 10 répétitions | N7: 1. Petite amplitude (8 rép.) 2. Amplitude complète (10 rép.) 3. Pause de 2 s en bas (10 rép.) | O7: Adducteurs, Quadriceps, Grand fessier | P7: Moyen fessier | Q7: 3.8 (code 02022, Callisthénie modérée (pompes, fentes)) | R7: Debout, pieds joints. Fais un grand pas sur le côté. Plie le genou de ce côté et pousse les fesses en arrière, l'autre jambe reste tendue. Reviens au centre en poussant sur le pied. Alterne. | S7: Les deux pieds restent à plat et pointent vers l'avant. | T7: Inspire en descendant, expire en revenant. | U7: Genou plié qui rentre vers l'intérieur. Dos arrondi. | V7: free-exercise-db (domaine public), fiche Barbell Side Split Squat : https://github.com/yuhonas/free-exercise-db/blob/main/exercises/Barbell_Side_Split_Squat.json | W7: Musculation des cuisses : fentes latérales (français) https://www.youtube.com/watch?v=3EvkUQHvFkI
A8: fente_bulgare | B8: Fente bulgare (pied arrière sur une chaise) | C8: Nouveau | G8: renforcement | H8: jambes, fessiers | I8: renforcer, tonifier | J8: 4 | K8: non | L8: chaise | M8: 8 répétitions | N8: 1. Petite amplitude, main au mur (6 rép.) 2. Amplitude complète (8 rép.) 3. Descente lente en 3 s (8 rép.) 4. Haltères en main (8 rép.) | O8: Quadriceps, Grand fessier | P8: Ischio-jambiers, Adducteurs, Moyen fessier | Q8: 3.8 (code 02022, Callisthénie modérée (pompes, fentes)) | R8: Dos à une chaise stable, pose le dessus du pied arrière sur l'assise. Descends à la verticale sur la jambe avant, buste légèrement penché. Remonte en poussant dans le talon avant. Fais toutes les répétitions, puis change. | S8: Chaise calée contre un mur pour qu'elle ne glisse pas. | T8: Inspire en descendant, expire en remontant. | U8: Pied avant trop près de la chaise. Pousser avec la jambe arrière. | V8: free-exercise-db (domaine public), fiche Split Squats : https://github.com/yuhonas/free-exercise-db/blob/main/exercises/Split_Squats.json | W8: Fentes bulgares sur chaise : exécution, technique, conseils et progression (français) https://www.youtube.com/watch?v=M1xhRlf8poM
A9: pont_unilateral | B9: Pont fessier sur une jambe | C9: Nouveau | G9: renforcement | H9: fessiers, jambes | I9: renforcer, tonifier | J9: 3 | K9: non | L9: aucun | M9: 10 répétitions | N9: 1. Jambe libre pliée (8 rép.) 2. Jambe libre tendue (10 rép.) 3. Pause de 2 s en haut (10 rép.) | O9: Grand fessier | P9: Ischio-jambiers, Moyen fessier, Bas du dos (lombaires) | Q9: 3 (code 02056, Renforcement au poids du corps, général) | R9: Allonge-toi sur le dos, un pied à plat, l'autre jambe en l'air. Pousse dans le talon au sol et monte le bassin bien droit. Redescends lentement. Change de jambe à mi-série. | S9: Le bassin reste horizontal : s'il penche, reviens au pont sur deux jambes. | T9: Expire en montant, inspire en redescendant. | U9: Bassin qui penche du côté de la jambe levée. Cambrer le dos en haut. | V9: free-exercise-db (domaine public), fiche Single Leg Glute Bridge : https://github.com/yuhonas/free-exercise-db/blob/main/exercises/Single_Leg_Glute_Bridge.json | W9: Pont fessier à une jambe : single leg glute bridge (français) https://www.youtube.com/watch?v=43qFZebHGj8
A10: hip_thrust | B10: Hip thrust, épaules sur le canapé | C10: Nouveau | G10: renforcement | H10: fessiers | I10: renforcer, tonifier | J10: 3 | K10: non | L10: aucun | M10: 12 répétitions | N10: 1. Poids du corps (10 rép.) 2. Poids du corps, pause de 2 s (12 rép.) 3. Haltère posé sur le bassin (12 rép.) 4. Une jambe (8 rép.) | O10: Grand fessier | P10: Ischio-jambiers, Quadriceps | Q10: 3 (code 02056, Renforcement au poids du corps, général) | R10: Assieds-toi au sol, le haut du dos appuyé contre le bord d'un canapé ou d'un lit. Pieds à plat, pousse dans les talons pour monter le bassin jusqu'à l'horizontale. Menton rentré, serre les fessiers en haut, puis redescends. | S10: Le support doit être stable et bas (hauteur de genou environ). | T10: Expire en montant, inspire en redescendant. | U10: Cambrer le bas du dos en haut. Regarder le plafond : la nuque se casse. | V10: free-exercise-db (domaine public), fiche Barbell Hip Thrust : https://github.com/yuhonas/free-exercise-db/blob/main/exercises/Barbell_Hip_Thrust.json | W10: Tuto : muscler les fessiers avec le hip thrust (Decathlon) (français) https://www.youtube.com/watch?v=34xR5kn02xY
A11: ruade | B11: Ruade (donkey kick) | C11: Nouveau | G11: renforcement | H11: fessiers | I11: tonifier, renforcer | J11: 2 | K11: non | L11: aucun | M11: 12 répétitions | N11: 1. Petite amplitude (10 rép.) 2. Amplitude complète (12 rép.) 3. Élastique autour des cuisses (12 rép.) 4. Pause de 2 s en haut (15 rép.) | O11: Grand fessier | P11: Ischio-jambiers, Abdominaux profonds | Q11: 3 (code 02056, Renforcement au poids du corps, général) | R11: À quatre pattes, mains sous les épaules, genoux sous les hanches. Genou plié à angle droit, pousse la plante du pied vers le plafond. Reviens sans poser le genou. Change de côté à mi-série. | S11: Monte seulement tant que le dos reste plat. | T11: Expire en poussant, inspire en revenant. | U11: Creuser le dos pour monter plus haut. Ouvrir la hanche sur le côté. | V11: free-exercise-db (domaine public), fiche Glute Kickback : https://github.com/yuhonas/free-exercise-db/blob/main/exercises/Glute_Kickback.json | W11: How To: Donkey Kicks for Glute Strength (anglais) https://www.youtube.com/watch?v=vElEKAdulIE
A12: bouche_incendie | B12: Bouche d'incendie (fire hydrant) | C12: Nouveau | G12: renforcement | H12: fessiers | I12: tonifier, renforcer | J12: 2 | K12: non | L12: aucun | M12: 12 répétitions | N12: 1. Petite amplitude (10 rép.) 2. Amplitude complète (12 rép.) 3. Élastique autour des cuisses (12 rép.) | O12: Moyen fessier | P12: Grand fessier, Abdominaux profonds | Q12: 3 (code 02056, Renforcement au poids du corps, général) | R12: À quatre pattes, dos plat. Garde le genou plié et ouvre la cuisse sur le côté, comme une porte. Redescends lentement. Change de côté à mi-série. | S12: Le buste ne bascule pas : seule la jambe bouge. | T12: Expire en ouvrant, inspire en refermant. | U12: Pencher tout le corps du côté opposé. Aller trop vite. | V12: free-exercise-db (domaine public), fiche Thigh Abductor : https://github.com/yuhonas/free-exercise-db/blob/main/exercises/Thigh_Abductor.json | W12: Fire hydrants : exécution, technique, conseils et progression (français) https://www.youtube.com/watch?v=6yoip-ClM34
A13: charniere_hanche | B13: Charnière de hanche (good morning) au poids du corps | C13: Nouveau | G13: renforcement | H13: jambes, dos, fessiers | I13: renforcer, mobilite | J13: 2 | K13: non | L13: aucun | M13: 12 répétitions | N13: 1. Mains sur les hanches (10 rép.) 2. Mains derrière la tête (12 rép.) 3. Élastique sous les pieds, sur la nuque (12 rép.) | O13: Ischio-jambiers, Grand fessier | P13: Bas du dos (lombaires) | Q13: 3 (code 02056, Renforcement au poids du corps, général) | R13: Debout, pieds largeur de hanches, genoux légèrement fléchis. Pousse les fesses loin en arrière, le buste descend dos plat. Arrête quand tu sens l'arrière des cuisses tirer, puis remonte en serrant les fessiers. | S13: Le dos reste plat du début à la fin : c'est la hanche qui plie. | T13: Inspire en descendant, expire en remontant. | U13: Arrondir le dos. Plier les genoux comme pour un squat. | V13: free-exercise-db (domaine public), fiche Band Good Morning : https://github.com/yuhonas/free-exercise-db/blob/main/exercises/Band_Good_Morning.json | W13: How to Do a Good Morning Exercise (Perfect Hip Hinge Form for Beginners) (anglais) https://www.youtube.com/watch?v=9ylRcYLSz40
... A15: squat_goblet | B15: Squat goblet à l'haltère | C15: Nouveau | G15: renforcement | H15: jambes, fessiers | I15: renforcer | J15: 3 | K15: non | L15: halteres | M15: 10 répétitions | N15: 1. Haltère léger (10 rép.) 2. Haltère moyen (10 rép.) 3. Pause de 2 s en bas (10 rép.) 4. Haltère lourd (8 rép.) | O15: Quadriceps, Grand fessier | P15: Adducteurs, Abdominaux profonds, Bas du dos (lombaires) | Q15: 5 (code 02052, Squats et soulevés de terre) | R15: Tiens un haltère vertical contre la poitrine, coudes vers le bas. Descends en squat, les coudes passent entre les genoux. Remonte en poussant dans les talons, buste droit. | S15: L'haltère reste collé à la poitrine pendant tout le mouvement. | T15: Inspire en descendant, expire en remontant. | U15: Laisser l'haltère tirer le buste vers l'avant. Talons qui décollent. | V15: free-exercise-db (domaine public), fiche Goblet Squat : https://github.com/yuhonas/free-exercise-db/blob/main/exercises/Goblet_Squat.json | W15: Goblet squat : exécution, technique, conseils et progression (français) https://www.youtube.com/watch?v=QNPVhVsJS2A
A16: releve_mollets_unipodal | B16: Montée sur pointe, une jambe | C16: Nouveau | G16: renforcement | H16: jambes | I16: renforcer, tonifier | J16: 2 | K16: non | L16: mur | M16: 12 répétitions | N16: 1. Main au mur, amplitude confortable (10 rép.) 2. Descente lente en 3 s (12 rép.) 3. Talon dans le vide, sur une marche (12 rép.) | O16: Mollets | Q16: 3 (code 02056, Renforcement au poids du corps, général) | R16: Debout sur une jambe, une main au mur pour l'équilibre. Monte le plus haut possible sur la pointe du pied. Redescends lentement. Change de jambe. | S16: Le genou reste juste déverrouillé. | T16: Expire en montant, inspire en descendant. | U16: Rebondir en bas. Cheville qui part vers l'extérieur. | V16: free-exercise-db (domaine public), fiche Standing Dumbbell Calf Raise : https://github.com/yuhonas/free-exercise-db/blob/main/exercises/Standing_Dumbbell_Calf_Raise.json | W16: Mollets : mollets debout à une jambe (français) https://www.youtube.com/watch?v=jGUplusFlEY
A17: adducteurs_couche | B17: Levée de jambe intérieure (adducteurs) | C17: Nouveau | G17: renforcement | H17: jambes | I17: tonifier, renforcer | J17: 1 | K17: non | L17: aucun | M17: 15 répétitions | N17: 1. Petite amplitude (12 rép.) 2. Pause de 2 s en haut (15 rép.) 3. Élastique aux chevilles (15 rép.) | O17: Adducteurs | P17: Abdominaux profonds | Q17: 3 (code 02056, Renforcement au poids du corps, général) | R17: Allonge-toi sur le côté, la jambe du dessus pliée et posée devant toi. Monte la jambe du dessous tendue, de quelques centimètres. Redescends sans poser complètement. Change de côté. | S17: Petit mouvement, sans élan. | T17: Expire en montant, inspire en descendant. | U17: Rouler vers l'arrière. Pointe du pied tournée vers le plafond. | V17: free-exercise-db (domaine public), fiche Thigh Adductor : https://github.com/yuhonas/free-exercise-db/blob/main/exercises/Thigh_Adductor.json free-exercise-db (domaine public), fiche Band Hip Adductions : https://github.com/yuhonas/free-exercise-db/blob/main/exercises/Band_Hip_Adductions.json | W17: Exercice intérieur des cuisses (adducteurs) : levé de jambe allongé (français) https://www.youtube.com/watch?v=3EiBfcTLZDE
A18: pont_marche | B18: Pont fessier en marche | C18: Nouveau | G18: gainage | H18: fessiers, abdos | I18: renforcer | J18: 3 | K18: non | L18: aucun | M18: 10 répétitions | N18: 1. Pied soulevé de 5 cm (8 rép.) 2. Genou ramené vers la poitrine (10 rép.) 3. Pause de 2 s par pas (10 rép.) | O18: Grand fessier, Abdominaux profonds | P18: Ischio-jambiers, Obliques | Q18: 2.8 (code 02024, Callisthénie légère (crunchs, planche)) | R18: En position de pont, bassin levé. Soulève un pied, puis l'autre, comme si tu marchais sur place. Le bassin reste haut et immobile. | S18: Si le bassin tourne ou descend, reviens au pont classique. | T18: Respire à chaque pas, sans bloquer. | U18: Bassin qui s'affaisse. Hanches qui basculent d'un côté à l'autre. | V18: free-exercise-db (domaine public), fiche Butt Lift Bridge : https://github.com/yuhonas/free-exercise-db/blob/main/exercises/Butt_Lift_Bridge.json | W18: How to Do a Glute Bridge March (anglais) https://www.youtube.com/watch?v=8-invS7-Ugo
A19: squat_unipodal_chaise | B19: Squat sur une jambe vers une chaise | C19: Nouveau | G19: calisthenie | H19: jambes, fessiers | I19: renforcer | J19: 4 | K19: non | L19: chaise | M19: 6 répétitions | N19: 1. Chaise haute, une main au mur (5 rép.) 2. Chaise haute (6 rép.) 3. Chaise basse (6 rép.) 4. Descente lente en 4 s (6 rép.) | O19: Quadriceps, Grand fessier | P19: Moyen fessier, Ischio-jambiers, Abdominaux profonds | Q19: 3.8 (code 02022, Callisthénie modérée (pompes, fentes)) | R19: Debout devant une chaise, sur une jambe, l'autre tendue devant toi. Descends lentement jusqu'à t'asseoir, bras tendus devant pour l'équilibre. Relève-toi sur la même jambe. Change de jambe. | S19: Étape vers le pistol squat. Pose les deux pieds si le genou rentre vers l'intérieur. | T19: Inspire en descendant, expire en te relevant. | U19: Se laisser tomber sur la chaise. Genou qui part vers l'intérieur. | V19: free-exercise-db (domaine public), fiche Single-Leg High Box Squat : https://github.com/yuhonas/free-exercise-db/blob/main/exercises/Single-Leg_High_Box_Squat.json free-exercise-db (domaine public), fiche Kettlebell Pistol Squat : https://github.com/yuhonas/free-exercise-db/blob/main/exercises/Kettlebell_Pistol_Squat.json | W19: Pistol squat, squat à 1 jambe (alternatives et progression) (français) https://www.youtube.com/watch?v=STa-MCOn3xM
A20: pompe_mur | B20: Pompe au mur | C20: Nouveau | G20: renforcement | H20: bras, epaules | I20: renforcer, tonifier | J20: 1 | K20: non | L20: mur | M20: 12 répétitions | N20: 1. Pieds proches du mur (10 rép.) 2. Pieds plus éloignés (12 rép.) 3. Descente lente en 3 s (12 rép.) | O20: Pectoraux, Triceps | P20: Épaules (avant), Abdominaux profonds | Q20: 3 (code 02056, Renforcement au poids du corps, général) | R20: Face au mur, mains à plat à hauteur d'épaules, un peu plus écartées. Plie les coudes pour approcher la poitrine du mur, corps gainé. Repousse le mur pour revenir. | S20: Plus les pieds sont loin du mur, plus c'est difficile. | T20: Inspire en descendant, expire en poussant. | U20: Coudes ouverts à 90° du corps. Fesses en arrière. | V20: NHS, Strength exercises : https://www.nhs.uk/live-well/exercise/strength-and-flexibility-exercises/strength-exercises/ free-exercise-db (domaine public), fiche Incline Push-Up : https://github.com/yuhonas/free-exercise-db/blob/main/exercises/Incline_Push-Up.json | W20: Pompes contre le mur pour débutants (français) https://www.youtube.com/watch?v=emhF1efZ-38
A21: pompe_inclinee | B21: Pompe inclinée (mains sur une chaise) | C21: Nouveau | G21: renforcement | H21: bras, epaules | I21: renforcer, tonifier | J21: 2 | K21: non | L21: chaise | M21: 10 répétitions | N21: 1. Mains sur un plan haut (table) (8 rép.) 2. Mains sur l'assise (10 rép.) 3. Descente lente en 3 s (10 rép.) | O21: Pectoraux, Triceps | P21: Épaules (avant), Abdominaux profonds | Q21: 3.8 (code 02022, Callisthénie modérée (pompes, fentes)) | R21: Mains sur l'assise d'une chaise calée contre le mur, corps en planche. Descends la poitrine vers la chaise, coudes à 45° du corps. Pousse pour revenir, corps bien aligné. | S21: La chaise ne doit pas pouvoir glisser. | T21: Inspire en descendant, expire en poussant. | U21: Bassin qui s'affaisse. Tête qui avance vers la chaise. | V21: free-exercise-db (domaine public), fiche Incline Push-Up : https://github.com/yuhonas/free-exercise-db/blob/main/exercises/Incline_Push-Up.json | W21: Pompes inclinées (français) https://www.youtube.com/watch?v=pH9hQDirfog
A22: pompe_genoux | B22: Pompe sur les genoux | C22: Nouveau | G22: renforcement | H22: bras, epaules | I22: renforcer, tonifier | J22: 2 | K22: non | L22: aucun | M22: 10 répétitions | N22: 1. Demi-amplitude (8 rép.) 2. Amplitude complète (10 rép.) 3. Descente lente en 3 s (10 rép.) | O22: Pectoraux, Triceps | P22: Épaules (avant), Abdominaux profonds | Q22: 3.8 (code 02022, Callisthénie modérée (pompes, fentes)) | R22: À genoux, mains au sol sous les épaules, un peu plus écartées. Aligne genoux, hanches et épaules, puis descends la poitrine vers le sol. Repousse le sol pour remonter. | S22: Un coussin sous les genoux rend l'exercice plus confortable. | T22: Inspire en descendant, expire en poussant. | U22: Fesses en l'air. Coudes ouverts sur les côtés. | V22: free-exercise-db (domaine public), fiche Pushups : https://github.com/yuhonas/free-exercise-db/blob/main/exercises/Pushups.json | W22: Pompe sur les genoux : démonstration, explication et conseils (français) https://www.youtube.com/watch?v=SWUw2epT8P4
A23: pompe | B23: Pompe | C23: Nouveau | G23: calisthenie | H23: bras, epaules, abdos | I23: renforcer | J23: 3 | K23: non | L23: aucun | M23: 10 répétitions | N23: 1. 5 pompes propres (5 rép.) 2. 8 pompes (8 rép.) 3. 10 pompes (10 rép.) 4. Descente lente en 3 s (10 rép.) | O23: Pectoraux, Triceps | P23: Épaules (avant), Abdominaux (grand droit), Abdominaux profonds | Q23: 3.8 (code 02022, Callisthénie modérée (pompes, fentes)) | R23: Mains au sol un peu plus larges que les épaules, corps droit de la tête aux talons. Descends la poitrine jusqu'à quelques centimètres du sol, coudes à 45°. Pousse le sol pour revenir, sans casser l'alignement. | S23: Si le bassin s'affaisse, passe à la pompe sur les genoux. | T23: Inspire en descendant, expire en poussant. | U23: Bassin qui s'affaisse. Tête qui plonge vers le sol. Coudes à 90° du corps. | V23: free-exercise-db (domaine public), fiche Pushups : https://github.com/yuhonas/free-exercise-db/blob/main/exercises/Pushups.json | W23: Comment bien faire les pompes (évitez les erreurs courantes et progressez) (français) https://www.youtube.com/watch?v=V9TUK5IdRrY
A24: pompe_serree | B24: Pompe mains serrées (triceps) | C24: Nouveau | G24: calisthenie | H24: bras | I24: renforcer | J24: 4 | K24: non | L24: aucun | M24: 8 répétitions | N24: 1. Sur les genoux (8 rép.) 2. Sur les pieds (6 rép.) 3. Sur les pieds (8 rép.) | O24: Triceps | P24: Pectoraux, Épaules (avant) | Q24: 3.8 (code 02022, Callisthénie modérée (pompes, fentes)) | R24: En position de pompe, mains sous les épaules, rapprochées. Descends en gardant les coudes collés au corps. Pousse pour remonter. | S24: Plus exigeant pour les poignets : écarte un peu les mains si besoin. | T24: Inspire en descendant, expire en poussant. | U24: Coudes qui s'ouvrent. Bassin qui s'affaisse. | V24: free-exercise-db (domaine public), fiche Push-Ups - Close Triceps Position : https://github.com/yuhonas/free-exercise-db/blob/main/exercises/Push-Ups_-_Close_Triceps_Position.json | W24: Les pompes prise serrée pour les triceps (pour qui, comment, variantes) (français) https://www.youtube.com/watch?v=FvnPL4cYUQk
A25: pompe_pike | B25: Pompe en V (pike push-up) | C25: Nouveau | G25: calisthenie | H25: epaules, bras | I25: renforcer | J25: 4 | K25: non | L25: aucun | M25: 8 répétitions | N25: 1. Petite amplitude (6 rép.) 2. Front vers le sol (8 rép.) 3. Pieds surélevés sur une chaise (6 rép.) | O25: Épaules (avant), Triceps | P25: Trapèzes, Pectoraux | Q25: 3.8 (code 02022, Callisthénie modérée (pompes, fentes)) | R25: Mains au sol, fesses hautes : ton corps forme un V à l'envers. Plie les coudes pour descendre le sommet du crâne vers le sol, entre les mains. Repousse pour revenir. | S25: Descends lentement : le poids est sur les épaules et la tête approche du sol. | T25: Inspire en descendant, expire en poussant. | U25: Coudes qui partent sur les côtés. Fesses qui descendent : ça devient une pompe classique. | V25: free-exercise-db (domaine public), fiche Handstand Push-Ups : https://github.com/yuhonas/free-exercise-db/blob/main/exercises/Handstand_Push-Ups.json | W25: Pike push up (niveau 1) (français) https://www.youtube.com/watch?v=NrkGYnsgbOA
A26: dips_chaise | B26: Dips sur chaise | C26: Nouveau | G26: calisthenie | H26: bras | I26: renforcer, tonifier | J26: 3 | K26: non | L26: chaise | M26: 10 répétitions | N26: 1. Genoux pliés, petite amplitude (8 rép.) 2. Genoux pliés (10 rép.) 3. Jambes tendues (10 rép.) | O26: Triceps | P26: Pectoraux, Épaules (avant) | Q26: 3.8 (code 02022, Callisthénie modérée (pompes, fentes)) | R26: Dos à une chaise stable, mains sur le bord de l'assise, doigts vers l'avant. Plie les coudes vers l'arrière pour descendre les fesses. Remonte en tendant les bras. | S26: Descends jusqu'à ce que les bras soient à angle droit, pas plus bas. | T26: Inspire en descendant, expire en poussant. | U26: Épaules qui remontent vers les oreilles. Coudes qui s'écartent. S'éloigner de la chaise. | V26: free-exercise-db (domaine public), fiche Bench Dips : https://github.com/yuhonas/free-exercise-db/blob/main/exercises/Bench_Dips.json | W26: Dips sur chaise : exécution, technique, conseils et progression (français) https://www.youtube.com/watch?v=hIB3YWZk834
A27: rowing_haltere | B27: Rowing à un bras à l'haltère | C27: Nouveau | G27: renforcement | H27: dos, bras | I27: renforcer, tonifier | J27: 2 | K27: non | L27: halteres | M27: 12 répétitions | N27: 1. Haltère léger (12 rép.) 2. Haltère moyen (10 rép.) 3. Pause de 2 s coude en arrière (10 rép.) | O27: Grand dorsal, Haut du dos (rhomboïdes) | P27: Biceps, Épaules (arrière) | Q27: 3.5 (code 02054, Renforcement, 8 à 15 répétitions, résistance variée) | R27: Une main et un genou sur une chaise, l'autre pied au sol, dos plat. Tire l'haltère vers la hanche, coude près du corps. Redescends lentement. Change de côté. | S27: Le dos reste plat et immobile, sans rotation. | T27: Expire en tirant, inspire en descendant. | U27: Tourner le buste pour monter l'haltère. Tirer vers l'épaule au lieu de la hanche. | V27: free-exercise-db (domaine public), fiche One-Arm Dumbbell Row : https://github.com/yuhonas/free-exercise-db/blob/main/exercises/One-Arm_Dumbbell_Row.json | W27: Musculation du dos : le rowing haltère à 1 bras (français) https://www.youtube.com/watch?v=VLzDhlGdpS0
A28: developpe_epaules | B28: Développé épaules aux haltères | C28: Nouveau | G28: renforcement | H28: epaules, bras | I28: renforcer, tonifier | J28: 3 | K28: non | L28: halteres | M28: 10 répétitions | N28: 1. Assis, haltères légers (10 rép.) 2. Debout (10 rép.) 3. Haltères moyens (10 rép.) | O28: Épaules (avant), Épaules (côté) | P28: Triceps, Trapèzes | Q28: 3.5 (code 02054, Renforcement, 8 à 15 répétitions, résistance variée) | R28: Haltères à hauteur d'épaules, paumes vers l'avant, ventre gainé. Pousse vers le haut jusqu'à tendre les bras. Redescends lentement à hauteur d'oreilles. | S28: Ne cambre pas le bas du dos pour pousser : allège la charge. | T28: Expire en poussant, inspire en descendant. | U28: Cambrer le dos. Descendre trop vite. | V28: free-exercise-db (domaine public), fiche Dumbbell Shoulder Press : https://github.com/yuhonas/free-exercise-db/blob/main/exercises/Dumbbell_Shoulder_Press.json | W28: Technique du développé épaules aux haltères (assis ou debout) (français) https://www.youtube.com/watch?v=CE9KiCPFw0E
A29: curl_marteau | B29: Curl marteau aux haltères | C29: Nouveau | G29: renforcement | H29: bras | I29: renforcer, tonifier | J29: 2 | K29: non | L29: halteres | M29: 12 répétitions | N29: 1. Haltères légers (12 rép.) 2. Haltères moyens (10 rép.) 3. Descente lente en 3 s (10 rép.) | O29: Biceps, Avant-bras | Q29: 3.5 (code 02054, Renforcement, 8 à 15 répétitions, résistance variée) | R29: Debout, un haltère dans chaque main, paumes face à face. Plie les coudes pour monter les haltères vers les épaules. Redescends lentement, coudes collés au corps. | S29: Pas d'élan avec le dos. | T29: Expire en montant, inspire en descendant. | U29: Balancer le buste. Coudes qui avancent. | V29: free-exercise-db (domaine public), fiche Hammer Curls : https://github.com/yuhonas/free-exercise-db/blob/main/exercises/Hammer_Curls.json | W29: Comment faire un curl marteau : technique correcte pour les biceps (français) https://www.youtube.com/watch?v=CsZSbMuqDYw
A30: extension_triceps_haltere | B30: Extension des triceps au-dessus de la tête | C30: Nouveau | G30: renforcement | H30: bras | I30: renforcer, tonifier | J30: 2 | K30: non | L30: halteres | M30: 12 répétitions | N30: 1. Assis, haltère léger (12 rép.) 2. Debout (12 rép.) 3. Haltère moyen (10 rép.) | O30: Triceps | Q30: 3.5 (code 02054, Renforcement, 8 à 15 répétitions, résistance variée) | R30: Tiens un haltère à deux mains au-dessus de la tête. Plie les coudes pour descendre l'haltère derrière la nuque. Tends les bras pour remonter, coudes pointés vers l'avant. | S30: Garde les côtes basses : pas de cambrure. | T30: Inspire en descendant, expire en tendant. | U30: Coudes qui s'écartent. Cambrer le dos. | V30: free-exercise-db (domaine public), fiche Standing Dumbbell Triceps Extension : https://github.com/yuhonas/free-exercise-db/blob/main/exercises/Standing_Dumbbell_Triceps_Extension.json | W30: Extension triceps avec haltère : démonstration, muscles, variantes, conseils et progression (français) https://www.youtube.com/watch?v=Reitru3_Srk
A31: oiseau_haltere | B31: Oiseau aux haltères (arrière d'épaule) | C31: Nouveau | G31: renforcement | H31: epaules, dos | I31: renforcer, tonifier | J31: 2 | K31: non | L31: halteres | M31: 12 répétitions | N31: 1. Haltères très légers (12 rép.) 2. Pause de 2 s bras ouverts (12 rép.) 3. Haltères légers (12 rép.) | O31: Épaules (arrière), Haut du dos (rhomboïdes) | P31: Trapèzes | Q31: 3.5 (code 02054, Renforcement, 8 à 15 répétitions, résistance variée) | R31: Penché en avant, dos plat, genoux fléchis, haltères sous les épaules. Ouvre les bras sur les côtés, coudes légèrement fléchis. Serre les omoplates en haut, puis redescends lentement. | S31: Des charges très légères suffisent. | T31: Expire en ouvrant, inspire en redescendant. | U31: Se redresser pour monter les bras. Hausser les épaules. | V31: free-exercise-db (domaine public), fiche Bent Over Low-Pulley Side Lateral : https://github.com/yuhonas/free-exercise-db/blob/main/exercises/Bent_Over_Low-Pulley_Side_Lateral.json | W31: Oiseau buste penché avec haltères (français) https://www.youtube.com/watch?v=mzbY2Vd0Mts
A32: developpe_sol | B32: Développé au sol aux haltères | C32: Nouveau | G32: renforcement | H32: bras, epaules | I32: renforcer | J32: 2 | K32: non | L32: halteres | M32: 12 répétitions | N32: 1. Haltères légers (12 rép.) 2. Haltères moyens (10 rép.) 3. Pause de 1 s coudes au sol (10 rép.) | O32: Pectoraux, Triceps | P32: Épaules (avant) | Q32: 3.5 (code 02054, Renforcement, 8 à 15 répétitions, résistance variée) | R32: Allongé sur le dos, genoux pliés, un haltère dans chaque main. Pousse les haltères vers le plafond jusqu'à tendre les bras. Redescends jusqu'à poser doucement les coudes au sol. | S32: Coudes à environ 45° du corps. | T32: Expire en poussant, inspire en descendant. | U32: Laisser tomber les coudes au sol. Coudes à angle droit du corps. | V32: free-exercise-db (domaine public), fiche Dumbbell Floor Press : https://github.com/yuhonas/free-exercise-db/blob/main/exercises/Dumbbell_Floor_Press.json | W32: Développé couché au sol : un développé couché pas comme les autres (français) https://www.youtube.com/watch?v=WVfLGkuhHHU
A33: tirage_vertical_elastique | B33: Tirage vertical à l'élastique | C33: Nouveau | G33: renforcement | H33: dos, bras | I33: renforcer, tonifier | J33: 2 | K33: non | L33: elastique | M33: 12 répétitions | N33: 1. Élastique léger (12 rép.) 2. Élastique moyen (12 rép.) 3. Pause de 2 s en bas (10 rép.) | O33: Grand dorsal | P33: Biceps, Haut du dos (rhomboïdes) | Q33: 3.5 (code 02054, Renforcement, 8 à 15 répétitions, résistance variée) | R33: Élastique fixé en haut d'une porte fermée, à genoux face à la porte. Bras tendus vers le haut, tire les coudes vers les côtes. Remonte lentement en gardant les épaules basses. | S33: Vérifie que l'élastique est bien coincé dans une porte fermée à clé ou ouvrant vers l'extérieur. | T33: Expire en tirant, inspire en remontant. | U33: Se pencher en arrière. Hausser les épaules. | V33: free-exercise-db (domaine public), fiche Band Assisted Pull-Up : https://github.com/yuhonas/free-exercise-db/blob/main/exercises/Band_Assisted_Pull-Up.json | W33: Tirage vertical à l'élastique (français) https://www.youtube.com/watch?v=8rSNwrdPgN4
A34: developpe_elastique | B34: Développé épaules à l'élastique | C34: Nouveau | G34: renforcement | H34: epaules | I34: renforcer, tonifier | J34: 2 | K34: non | L34: elastique | M34: 12 répétitions | N34: 1. Élastique léger (12 rép.) 2. Élastique moyen (12 rép.) 3. Un bras à la fois (10 rép.) | O34: Épaules (avant), Épaules (côté) | P34: Triceps | Q34: 3.5 (code 02054, Renforcement, 8 à 15 répétitions, résistance variée) | R34: Debout sur l'élastique, mains à hauteur d'épaules. Pousse vers le haut jusqu'à tendre les bras. Redescends lentement. | S34: Ventre gainé, sans cambrer. | T34: Expire en poussant, inspire en descendant. | U34: Cambrer le dos. Pousser vers l'avant au lieu du haut. | V34: free-exercise-db (domaine public), fiche Shoulder Press - With Bands : https://github.com/yuhonas/free-exercise-db/blob/main/exercises/Shoulder_Press_-_With_Bands.json | W34: Développé militaire élastique : exercice debout pour les épaules (français) https://www.youtube.com/watch?v=Y28EDAb2ASY
A35: superman | B35: Superman | C35: Nouveau | G35: renforcement | H35: dos, fessiers | I35: renforcer | J35: 2 | K35: non | L35: aucun | M35: 10 répétitions | N35: 1. Bras seuls, puis jambes seules (8 rép.) 2. Bras et jambes ensemble (10 rép.) 3. Maintien de 3 s en haut (10 rép.) | O35: Bas du dos (lombaires), Grand fessier | P35: Haut du dos (rhomboïdes), Ischio-jambiers | Q35: 3.5 (code 02030, Callisthénie légère à modérée (exercices du dos, se relever du sol)) | R35: Allongé sur le ventre, bras tendus devant toi, front au sol. Décolle en même temps bras et jambes de quelques centimètres. Redescends lentement. | S35: Petite hauteur suffit : le regard reste vers le sol. | T35: Expire en montant, inspire en descendant. | U35: Lever la tête vers l'avant. Monter trop haut en forçant sur le bas du dos. | V35: free-exercise-db (domaine public), fiche Superman : https://github.com/yuhonas/free-exercise-db/blob/main/exercises/Superman.json | W35: Comment se muscler les lombaires et le bas du dos : superman (français) https://www.youtube.com/watch?v=O-DOcsnwAQY
A36: ytw | B36: Y, T, W au sol | C36: Nouveau | G36: renforcement | H36: dos, epaules | I36: renforcer, mobilite | J36: 2 | K36: non | L36: aucun | M36: 9 répétitions | N36: 1. 2 de chaque lettre (6 rép.) 2. 3 de chaque lettre (9 rép.) 3. 3 de chaque, pause de 2 s (9 rép.) | O36: Haut du dos (rhomboïdes), Trapèzes, Épaules (arrière) | P36: Coiffe des rotateurs, Bas du dos (lombaires) | Q36: 3.5 (code 02030, Callisthénie légère à modérée (exercices du dos, se relever du sol)) | R36: Allongé sur le ventre, front sur une serviette roulée. Décolle les bras en Y, puis en T, puis en W (coudes pliés, ramenés vers les côtes). Pouces vers le plafond, serre les omoplates à chaque lettre. | S36: Mouvement lent, épaules loin des oreilles. | T36: Expire en décollant les bras, inspire en les reposant. | U36: Décoller la poitrine en cambrant. Aller trop vite. | V36: free-exercise-db (domaine public), fiche Reverse Flyes With External Rotation : https://github.com/yuhonas/free-exercise-db/blob/main/exercises/Reverse_Flyes_With_External_Rotation.json | W36: Posture : l'exercice des lettres I, Y, T, W, A (français) https://www.youtube.com/watch?v=G0nPXt_TgRg
A37: rowing_inverse_table | B37: Rowing inversé sous une table | C37: Nouveau | G37: calisthenie | H37: dos, bras | I37: renforcer | J37: 4 | K37: non | L37: aucun | M37: 8 répétitions | N37: 1. Genoux pliés (6 rép.) 2. Genoux pliés (8 rép.) 3. Jambes tendues (8 rép.) | O37: Grand dorsal, Haut du dos (rhomboïdes) | P37: Biceps, Épaules (arrière), Abdominaux profonds | Q37: 3.8 (code 02022, Callisthénie modérée (pompes, fentes)) | R37: Allongé sous une table très solide, mains sur le bord, bras tendus. Corps gainé, tire la poitrine vers le bord de la table. Redescends lentement. | S37: Seulement avec une table lourde et stable qui ne peut pas basculer. Teste-la avant. | T37: Expire en tirant, inspire en redescendant. | U37: Bassin qui s'affaisse. Tirer avec le cou. | V37: free-exercise-db (domaine public), fiche Inverted Row : https://github.com/yuhonas/free-exercise-db/blob/main/exercises/Inverted_Row.json | W37: Rowing inversé sous une table : exercice pour renforcer le dos (français) https://www.youtube.com/watch?v=lcsEJQAbdiw
A38: crunch | B38: Crunch | C38: Nouveau | G38: renforcement | H38: abdos | I38: tonifier, renforcer | J38: 2 | K38: non | L38: aucun | M38: 15 répétitions | N38: 1. Mains sur les cuisses (12 rép.) 2. Mains croisées sur la poitrine (15 rép.) 3. Pause de 2 s en haut (15 rép.) | O38: Abdominaux (grand droit) | P38: Obliques | Q38: 2.8 (code 02024, Callisthénie légère (crunchs, planche)) | R38: Allongé sur le dos, genoux pliés, pieds à plat. Enroule le haut du dos pour décoller les omoplates. Redescends lentement sans reposer complètement la tête. | S38: Ne tire pas sur la nuque avec les mains. | T38: Expire en montant, inspire en redescendant. | U38: Tirer sur la tête. Monter trop haut avec élan. | V38: free-exercise-db (domaine public), fiche Crunches : https://github.com/yuhonas/free-exercise-db/blob/main/exercises/Crunches.json | W38: Comment bien faire les crunchs pour les abdos (français) https://www.youtube.com/watch?v=LEb7Juw9tMo
A39: crunch_inverse | B39: Crunch inversé | C39: Nouveau | G39: renforcement | H39: abdos | I39: tonifier, renforcer | J39: 2 | K39: non | L39: aucun | M39: 12 répétitions | N39: 1. Petite amplitude (10 rép.) 2. Bassin décollé (12 rép.) 3. Descente lente en 3 s (12 rép.) | O39: Abdominaux (grand droit) | P39: Obliques, Fléchisseurs de hanche | Q39: 2.8 (code 02024, Callisthénie légère (crunchs, planche)) | R39: Allongé sur le dos, genoux pliés au-dessus des hanches, bras le long du corps. Ramène les genoux vers la poitrine en décollant légèrement le bassin. Redescends lentement. | S39: On enroule le bassin, on ne balance pas les jambes. | T39: Expire en enroulant, inspire en revenant. | U39: Prendre de l'élan. Appuyer fort sur les mains. | V39: free-exercise-db (domaine public), fiche Reverse Crunch : https://github.com/yuhonas/free-exercise-db/blob/main/exercises/Reverse_Crunch.json | W39: Musculation des abdominaux : crunch inversé (français) https://www.youtube.com/watch?v=0bq05pA3bkA
A40: crunch_velo | B40: Crunch vélo | C40: Nouveau | G40: renforcement | H40: abdos | I40: tonifier, renforcer | J40: 3 | K40: non | L40: aucun | M40: 16 répétitions | N40: 1. Pieds proches du sol en alternance lente (12 rép.) 2. 16 alternances (16 rép.) 3. 20 alternances (20 rép.) | O40: Obliques, Abdominaux (grand droit) | P40: Fléchisseurs de hanche | Q40: 2.8 (code 02024, Callisthénie légère (crunchs, planche)) | R40: Allongé sur le dos, mains aux tempes, omoplates décollées. Amène un coude vers le genou opposé pendant que l'autre jambe s'allonge. Alterne lentement, comme un pédalage. | S40: Le bas du dos reste au sol. | T40: Expire à chaque rotation. | U40: Tirer sur la nuque. Aller vite et perdre le contrôle. | V40: free-exercise-db (domaine public), fiche Cross-Body Crunch : https://github.com/yuhonas/free-exercise-db/blob/main/exercises/Cross-Body_Crunch.json free-exercise-db (domaine public), fiche Elbow to Knee : https://github.com/yuhonas/free-exercise-db/blob/main/exercises/Elbow_to_Knee.json | W40: Crunch cycliste : un exercice pour la taille (français) https://www.youtube.com/watch?v=rsX2MJPzXrE
A41: releve_jambes | B41: Relevé de jambes | C41: Nouveau | G41: renforcement | H41: abdos | I41: renforcer | J41: 3 | K41: non | L41: aucun | M41: 10 répétitions | N41: 1. Genoux pliés (10 rép.) 2. Jambes tendues, petite amplitude (8 rép.) 3. Jambes tendues (10 rép.) | O41: Abdominaux (grand droit), Fléchisseurs de hanche | P41: Abdominaux profonds | Q41: 2.8 (code 02024, Callisthénie légère (crunchs, planche)) | R41: Allongé sur le dos, mains sous les fesses. Monte les jambes jusqu'à la verticale. Redescends lentement sans que le bas du dos décolle. | S41: Arrête la descente avant que le dos ne se creuse. | T41: Expire en montant, inspire en descendant. | U41: Dos qui se creuse en bas. Jambes qui tombent. | V41: free-exercise-db (domaine public), fiche Flat Bench Lying Leg Raise : https://github.com/yuhonas/free-exercise-db/blob/main/exercises/Flat_Bench_Lying_Leg_Raise.json | W41: Exercice abdos : relevé de jambes allongé (français) https://www.youtube.com/watch?v=RNgWIsjj5U8
...

Sheet Entraînements
A1: Identifiant | B1: Titre | C1: Type | D1: Validé | E1: Commentaire | F1: Niveau | G1: Zones | H1: Durée (min) | I1: Calories (estimation, poids du mode d'emploi) | J1: Tours | K1: Pause (s) | L1: Sauts | M1: Matériel | N1: Description | O1: Contenu
A2: prog_mobilite_s1 | B2: Mobilité douce | C2: Jour de programme | F2: 1 | G2: corps_entier | H2: 5 | I2: =ROUND(8.7*'Mode d''emploi'!$B$20/60,0) -> 9 | J2: 1 | K2: 10 | L2: non | M2: aucun | N2: Une séance courte pour délier le dos, les hanches et les épaules entre deux renforcements. | O2: Corps : Chat-vache Corps : Cercles de hanches Corps : Livre ouvert (rotation du haut du dos) Corps : Le plus grand étirement du monde Corps : Posture de l'enfant
A3: prog_mobilite_s2 | B3: Mobilité du dos et des hanches | C3: Jour de programme | F3: 1 | G3: corps_entier | H3: 6 | I3: =ROUND(11.8*'Mode d''emploi'!$B$20/60,0) -> 12 | J3: 1 | K3: 10 | L3: non | M3: aucun | N3: Mobilité active pour récupérer et bouger mieux. | O3: Corps : Chat-vache Corps : Cercles de bras Corps : Rotations du buste Corps : Le plus grand étirement du monde Corps : Fente basse (posture du croissant) Corps : Posture de l'enfant
A4: prog_mobilite_s3 | B4: Mobilité et salutation au soleil | C4: Jour de programme | F4: 1 | G4: corps_entier | H4: 7 | I4: =ROUND(15.3*'Mode d''emploi'!$B$20/60,0) -> 15 | J4: 1 | K4: 10 | L4: non | M4: aucun | N4: Mobilité puis deux salutations au soleil en douceur. | O4: Corps : Chat-vache Corps : Cercles de hanches Corps : Salutation au soleil (version douce) Corps : Le plus grand étirement du monde Corps : Sphinx Corps : Torsion allongée
A5: prog_mobilite_s4 | B5: Mobilité complète | C5: Jour de programme | F5: 1 | G5: corps_entier | H5: 9 | I5: =ROUND(20.7*'Mode d''emploi'!$B$20/60,0) -> 21 | J5: 1 | K5: 10 | L5: non | M5: aucun | N5: Une séance de mobilité plus longue pour finir le mois en souplesse. | O5: Corps : Chat-vache Corps : Cercles de bras Corps : Salutation au soleil (version douce) Corps : Le plus grand étirement du monde Corps : Fente basse (posture du croissant) Corps : Pigeon (version au sol) Corps : Torsion allongée
A6: prog_recup_s1 | B6: Récupération : étirements | C6: Jour de programme | F6: 1 | G6: corps_entier | H6: 7 | I6: =ROUND(13*'Mode d''emploi'!$B$20/60,0) -> 13 | J6: 1 | K6: 10 | L6: non | M6: aucun | N6: Étirements doux de tout le corps pour finir la semaine. | O6: Corps : Genoux à la poitrine Corps : Étirement des fessiers en « 4 » Corps : Étirement des ischio-jambiers Corps : Torsion allongée Corps : Posture de l'enfant Corps : Respiration costale
A7: prog_recup_s2 | B7: Récupération : yoga doux | C7: Jour de programme | F7: 1 | G7: corps_entier | H7: 9 | I7: =ROUND(13.6*'Mode d''emploi'!$B$20/60,0) -> 14 | J7: 1 | K7: 10 | L7: non | M7: aucun | N7: Postures de yoga au sol et respiration lente. | O7: Corps : Chat-vache Corps : Sphinx Corps : Posture de l'enfant Corps : Papillon Corps : Torsion allongée Corps : Respiration lente (6 cycles par minute)
A8: prog_recup_s3 | B8: Récupération : hanches et dos | C8: Jour de programme | F8: 1 | G8: corps_entier | H8: 9 | I8: =ROUND(14.9*'Mode d''emploi'!$B$20/60,0) -> 15 | J8: 1 | K8: 10 | L8: non | M8: aucun | N8: Ouverture des hanches, détente du dos et quelques minutes de calme. | O8: Corps : Fente basse (posture du croissant) Corps : Pigeon (version au sol) Corps : Papillon Corps : Bébé heureux Corps : Torsion allongée Corps : Genoux à la poitrine Corps : Respiration lente (6 cycles par minute)
A9: prog_recup_s4 | B9: Récupération : bilan du mois | C9: Jour de programme | F9: 1 | G9: corps_entier | H9: 10 | I9: =ROUND(13.7*'Mode d''emploi'!$B$20/60,0) -> 14 | J9: 1 | K9: 10 | L9: non | M9: aucun | N9: Étirements et scan corporel pour savourer le chemin parcouru. | O9: Corps : Chat-vache Corps : Pince assise Corps : Papillon Corps : Torsion allongée Corps : Méditation : scan corporel
A10: rf_s1_a | B10: Bas du corps et gainage | C10: Jour de programme | F10: 1 | G10: jambes, fessiers, abdos | H10: 11 | I10: =ROUND(22.7*'Mode d''emploi'!$B$20/60,0) -> 23 | J10: 2 | K10: 15 | L10: non | M10: aucun | O10: Échauffement : Marche sur place, genoux hauts Échauffement : Cercles de bras Échauffement : Cercles de hanches Échauffement : Rotations du buste Corps : Squat au poids du corps Corps : Pont fessier Corps : Dead bug Corps : Planche Retour au calme : Étirement des ischio-jambiers
A11: rf_s1_b | B11: Haut du corps et dos | C11: Jour de programme | F11: 1 | G11: bras, epaules, dos | H11: 9 | I11: =ROUND(20*'Mode d''emploi'!$B$20/60,0) -> 20 | J11: 2 | K11: 15 | L11: non | M11: aucun | O11: Échauffement : Marche sur place, genoux hauts Échauffement : Cercles de bras Échauffement : Cercles de hanches Échauffement : Rotations du buste Corps : Pompe sur les genoux Corps : Superman Corps : Bird-dog Corps : Position de l'ours (bear hold) Retour au calme : Posture de l'enfant
A12: rf_s1_c | B12: Cardio doux | C12: Jour de programme | F12: 1 | G12: corps_entier | H12: 8 | I12: =ROUND(24.6*'Mode d''emploi'!$B$20/60,0) -> 25 | J12: 2 | K12: 15 | L12: non | M12: aucun | O12: Échauffement : Cercles de bras Échauffement : Cercles de hanches Corps : Marche sur place, genoux hauts Corps : Jumping jacks sans saut Corps : Squat, coup de pied avant Corps : Boxe dans le vide Retour au calme : Chien tête en bas
A13: rf_s2_a | B13: Bas du corps et gainage | C13: Jour de programme | F13: 1 | G13: jambes, fessiers, abdos | H13: 14 | I13: =ROUND(31.5*'Mode d''emploi'!$B$20/60,0) -> 32 | J13: 2 | K13: 15 | L13: non | M13: aucun | O13: Échauffement : Marche sur place, genoux hauts Échauffement : Cercles de bras Échauffement : Cercles de hanches Échauffement : Rotations du buste Corps : Squat au poids du corps Corps : Fente arrière Corps : Pont fessier Corps : Dead bug Corps : Planche Retour au calme : Étirement des ischio-jambiers Retour au calme : Étirement des fléchisseurs de hanche
A14: rf_s2_b | B14: Haut du corps et dos | C14: Jour de programme | F14: 1 | G14: bras, epaules, dos | H14: 14 | I14: =ROUND(30.1*'Mode d''emploi'!$B$20/60,0) -> 30 | J14: 2 | K14: 15 | L14: non | M14: aucun | O14: Échauffement : Marche sur place, genoux hauts Échauffement : Cercles de bras Échauffement : Cercles de hanches Échauffement : Rotations du buste Corps : Pompe sur les genoux Corps : Superman Corps : Planche, touchers d'épaule Corps : Y, T, W au sol Corps : Bird-dog Corps : Planche inversée Retour au calme : Posture de l'enfant Retour au calme : Étirement de l'épaule, bras croisé
A15: rf_s2_c | B15: Cardio et renforcement | C15: Jour de programme | F15: 1 | G15: corps_entier | H15: 14 | I15: =ROUND(44*'Mode d''emploi'!$B$20/60,0) -> 44 | J15: 2 | K15: 15 | L15: non | M15: aucun | O15: Échauffement : Marche sur place, genoux hauts Échauffement : Cercles de bras Échauffement : Cercles de hanches Corps : Jumping jacks sans saut Corps : Squat au poids du corps Corps : Boxe dans le vide Corps : Mountain climbers lents Corps : Patineur sans saut Corps : Squat, coup de pied avant Retour au calme : Étirement des quadriceps debout Retour au calme : Chien tête en bas
A16: rf_s3_a | B16: Bas du corps et gainage | C16: Jour de programme | F16: 1 | G16: jambes, fessiers, abdos | H16: 20 | I16: =ROUND(45.4*'Mode d''emploi'!$B$20/60,0) -> 45 | J16: 3 | K16: 15 | L16: non | M16: aucun | O16: Échauffement : Marche sur place, genoux hauts Échauffement : Cercles de bras Échauffement : Cercles de hanches Échauffement : Rotations du buste Échauffement : Le plus grand étirement du monde Corps : Squat au poids du corps Corps : Fente arrière Corps : Pont fessier Corps : Dead bug Corps : Planche Retour au calme : Étirement des ischio-jambiers Retour au calme : Étirement des fléchisseurs de hanche
A17: rf_s3_b | B17: Haut du corps et dos | C17: Jour de programme | F17: 1 | G17: bras, epaules, dos | H17: 18 | I17: =ROUND(41.5*'Mode d''emploi'!$B$20/60,0) -> 42 | J17: 3 | K17: 15 | L17: non | M17: aucun | O17: Échauffement : Marche sur place, genoux hauts Échauffement : Cercles de bras Échauffement : Cercles de hanches Échauffement : Rotations du buste Échauffement : Le plus grand étirement du monde Corps : Pompe sur les genoux Corps : Superman Corps : Planche, touchers d'épaule Corps : Y, T, W au sol Corps : Planche inversée Retour au calme : Posture de l'enfant Retour au calme : Étirement de l'épaule, bras croisé
A18: rf_s3_c | B18: Cardio et renforcement | C18: Jour de programme | F18: 1 | G18: corps_entier | H18: 20 | I18: =ROUND(66.3*'Mode d''emploi'!$B$20/60,0) -> 66 | J18: 3 | K18: 15 | L18: non | M18: aucun | O18: Échauffement : Marche sur place, genoux hauts Échauffement : Cercles de bras Échauffement : Cercles de hanches Échauffement : Rotations du buste Corps : Jumping jacks sans saut Corps : Squat au poids du corps Corps : Boxe dans le vide Corps : Mountain climbers lents Corps : Burpee sans saut Corps : Squat, coup de pied avant Retour au calme : Étirement des quadriceps debout Retour au calme : Chien tête en bas
A19: rf_s4_a | B19: Bas du corps et gainage | C19: Jour de programme | F19: 2 | G19: jambes, fessiers, abdos | H19: 24 | I19: =ROUND(54.6*'Mode d''emploi'!$B$20/60,0) -> 55 | J19: 3 | K19: 15 | L19: non | M19: aucun | O19: Échauffement : Marche sur place, genoux hauts Échauffement : Cercles de bras Échauffement : Cercles de hanches Échauffement : Rotations du buste Échauffement : Le plus grand étirement du monde Corps : Squat au poids du corps Corps : Fente arrière Corps : Pont fessier Corps : Fente latérale Corps : Dead bug Corps : Planche Retour au calme : Étirement des ischio-jambiers Retour au calme : Étirement des fléchisseurs de hanche Retour au calme : Étirement des fessiers en « 4 »
A20: rf_s4_b | B20: Haut du corps et dos | C20: Jour de programme | F20: 2 | G20: bras, epaules, dos | H20: 26 | I20: =ROUND(66*'Mode d''emploi'!$B$20/60,0) -> 66 | J20: 3 | K20: 15 | L20: non | M20: aucun | O20: Échauffement : Marche sur place, genoux hauts Échauffement : Cercles de bras Échauffement : Cercles de hanches Échauffement : Rotations du buste Échauffement : Le plus grand étirement du monde Corps : Pompe sur les genoux Corps : Superman Corps : Planche, touchers d'épaule Corps : Y, T, W au sol Corps : Planche inversée Corps : Chenille (inchworm) Corps : Boxe dans le vide Corps : Position de l'ours (bear hold) Retour au calme : Posture de l'enfant Retour au calme : Étirement de l'épaule, bras croisé Retour au calme : Étirement des triceps
A21: rf_s4_c | B21: Cardio et renforcement | C21: Jour de programme | F21: 2 | G21: corps_entier | H21: 23 | I21: =ROUND(76.1*'Mode d''emploi'!$B$20/60,0) -> 76 | J21: 3 | K21: 15 | L21: non | M21: aucun | O21: Échauffement : Marche sur place, genoux hauts Échauffement : Cercles de bras Échauffement : Cercles de hanches Échauffement : Rotations du buste Échauffement : Le plus grand étirement du monde Corps : Jumping jacks sans saut Corps : Squat au poids du corps Corps : Boxe dans le vide Corps : Mountain climbers lents Corps : Burpee sans saut Corps : Patineur sans saut Retour au calme : Étirement des quadriceps debout Retour au calme : Chien tête en bas Retour au calme : Étirement latéral debout
A22: hf_s1_a | B22: Fessiers : les bases | C22: Jour de programme | F22: 1 | G22: fessiers | H22: 12 | I22: =ROUND(27.5*'Mode d''emploi'!$B$20/60,0) -> 28 | J22: 2 | K22: 15 | L22: non | M22: aucun | O22: Échauffement : Marche sur place, genoux hauts Échauffement : Cercles de hanches Échauffement : Balanciers de jambe Échauffement : Squat au poids du corps Corps : Pont fessier Corps : Clamshell (coquillage) Corps : Ruade (donkey kick) Corps : Levée de jambe sur le côté Retour au calme : Étirement des fessiers en « 4 »
A23: hf_s1_b | B23: Jambes et fessiers | C23: Jour de programme | F23: 1 | G23: jambes, fessiers | H23: 11 | I23: =ROUND(23.9*'Mode d''emploi'!$B$20/60,0) -> 24 | J23: 2 | K23: 15 | L23: non | M23: aucun | O23: Échauffement : Marche sur place, genoux hauts Échauffement : Cercles de hanches Échauffement : Balanciers de jambe Échauffement : Squat au poids du corps Corps : Squat sumo Corps : Fente arrière Corps : Bouche d'incendie (fire hydrant) Corps : Montée sur pointes de pieds Retour au calme : Étirement des quadriceps debout
A24: hf_s1_c | B24: Fessiers et abdos | C24: Jour de programme | F24: 1 | G24: fessiers, abdos | H24: 9 | I24: =ROUND(20*'Mode d''emploi'!$B$20/60,0) -> 20 | J24: 2 | K24: 15 | L24: non | M24: aucun | O24: Échauffement : Marche sur place, genoux hauts Échauffement : Cercles de hanches Échauffement : Rotations du buste Corps : Pont fessier en marche Corps : Dead bug Corps : Levée de jambe intérieure (adducteurs) Corps : Crunch inversé Retour au calme : Papillon
A25: hf_s2_a | B25: Fessiers : volume | C25: Jour de programme | F25: 1 | G25: fessiers | H25: 15 | I25: =ROUND(34.9*'Mode d''emploi'!$B$20/60,0) -> 35 | J25: 2 | K25: 15 | L25: non | M25: aucun | O25: Échauffement : Marche sur place, genoux hauts Échauffement : Cercles de hanches Échauffement : Balanciers de jambe Échauffement : Squat au poids du corps Corps : Pont fessier Corps : Hip thrust, épaules sur le canapé Corps : Clamshell (coquillage) Corps : Ruade (donkey kick) Corps : Levée de jambe sur le côté Retour au calme : Étirement des fessiers en « 4 » Retour au calme : Étirement des fléchisseurs de hanche
A26: hf_s2_b | B26: Jambes et fessiers | C26: Jour de programme | F26: 1 | G26: jambes, fessiers | H26: 14 | I26: =ROUND(32.1*'Mode d''emploi'!$B$20/60,0) -> 32 | J26: 2 | K26: 15 | L26: non | M26: aucun | O26: Échauffement : Marche sur place, genoux hauts Échauffement : Cercles de hanches Échauffement : Balanciers de jambe Échauffement : Squat au poids du corps Corps : Squat sumo Corps : Fente arrière Corps : Charnière de hanche (good morning) au poids du corps Corps : Bouche d'incendie (fire hydrant) Corps : Montée sur pointes de pieds Retour au calme : Étirement des quadriceps debout Retour au calme : Étirement des ischio-jambiers
A27: hf_s2_c | B27: Fessiers, abdos et cardio | C27: Jour de programme | F27: 1 | G27: fessiers, abdos | H27: 13 | I27: =ROUND(35*'Mode d''emploi'!$B$20/60,0) -> 35 | J27: 2 | K27: 15 | L27: non | M27: aucun | O27: Échauffement : Marche sur place, genoux hauts Échauffement : Cercles de hanches Échauffement : Rotations du buste Corps : Pont fessier en marche Corps : Patineur sans saut Corps : Dead bug Corps : Levée de jambe intérieure (adducteurs) Corps : Squat, coup de pied avant Retour au calme : Papillon Retour au calme : Étirement des fessiers en « 4 »
A28: hf_s3_a | B28: Fessiers : force | C28: Jour de programme | F28: 1 | G28: fessiers | H28: 21 | I28: =ROUND(47.9*'Mode d''emploi'!$B$20/60,0) -> 48 | J28: 3 | K28: 15 | L28: non | M28: aucun | O28: Échauffement : Marche sur place, genoux hauts Échauffement : Cercles de hanches Échauffement : Balanciers de jambe Échauffement : Squat au poids du corps Corps : Hip thrust, épaules sur le canapé Corps : Pont fessier sur une jambe Corps : Clamshell (coquillage) Corps : Ruade (donkey kick) Corps : Levée de jambe sur le côté Retour au calme : Étirement des fessiers en « 4 » Retour au calme : Étirement des fléchisseurs de hanche
